2024-11-07 14:38:09,309 ERROR: Exception on /dashboard [GET] [in C:\Users\mural\anaconda3\Lib\site-packages\flask\app.py:1744]
Traceback (most recent call last):
  File "C:\Users\mural\anaconda3\Lib\site-packages\flask\app.py", line 2529, in wsgi_app
    response = self.full_dispatch_request()
               ^^^^^^^^^^^^^^^^^^^^^^^^^^^^
  File "C:\Users\mural\anaconda3\Lib\site-packages\flask\app.py", line 1825, in full_dispatch_request
    rv = self.handle_user_exception(e)
         ^^^^^^^^^^^^^^^^^^^^^^^^^^^^^
  File "C:\Users\mural\anaconda3\Lib\site-packages\flask\app.py", line 1823, in full_dispatch_request
    rv = self.dispatch_request()
         ^^^^^^^^^^^^^^^^^^^^^^^
  File "C:\Users\mural\anaconda3\Lib\site-packages\flask\app.py", line 1799, in dispatch_request
    return self.ensure_sync(self.view_functions[rule.endpoint])(**view_args)
           ^^^^^^^^^^^^^^^^^^^^^^^^^^^^^^^^^^^^^^^^^^^^^^^^^^^^^^^^^^^^^^^^^
  File "C:\Users\mural\anaconda3\Lib\site-packages\flask_login\utils.py", line 290, in decorated_view
    return current_app.ensure_sync(func)(*args, **kwargs)
           ^^^^^^^^^^^^^^^^^^^^^^^^^^^^^^^^^^^^^^^^^^^^^^
  File "C:\chubb\python\project_folders\real_estate\app.py", line 108, in dashboard
    bed_avg_price = avg_val('bed', df, 'price')
                    ^^^^^^^^^^^^^^^^^^^^^^^^^^^
  File "C:\chubb\python\project_folders\real_estate\app.py", line 39, in avg_val
    x_axis = set(df[col_name1])
                 ~~^^^^^^^^^^^
  File "C:\Users\mural\anaconda3\Lib\site-packages\pandas\core\frame.py", line 3893, in __getitem__
    indexer = self.columns.get_loc(key)
              ^^^^^^^^^^^^^^^^^^^^^^^^^
  File "C:\Users\mural\anaconda3\Lib\site-packages\pandas\core\indexes\range.py", line 418, in get_loc
    raise KeyError(key)
KeyError: 'bed'
